Workbook

Sheet Read me
A1: GCC Market Report: Saudi Arabia
A2: Snapshot of the SFDA public Drugs List taken 2026-10-18: 8,207 products; 338 followed in the classes MSD competes in.
A3: Yellow cells are inputs. Everything else is a formula over the Products sheet: paste next month's products there and the pack recalculates.
A4: Price per unit = public pack price / pack size (a tablet, capsule, vial or pen). The riyal is pegged to the dollar; the rate is an input.
A5: US prices are the pharmacy acquisition cost (NADAC) per tablet, from Drug Price Watch; they are not net prices.
A6: An independent analysis of public data, not produced or endorsed by MSD or any company named.

Sheet Inputs
A1: Saudi riyals per US dollar | B1: 3.75
A2: Change the yellow cell; every USD figure follows.

Sheet Products
A1: Class | B1: Class name | C1: Ingredient | D1: Trade name | E1: Strength | F1: Unit | G1: Form | H1: Pack size | I1: Price SAR | J1: Price per unit SAR | K1: Price per unit USD | L1: Role | M1: Marketing company | N1: Local agent | O1: Registration no.
C2: LINAGLIPTIN | D2: OLPUNTRAMET | E2: 850,2.5 | F2: mg | G2: Film-coated tablet | H2: 60 | I2: 123.3 | J2: =IF(H2>0,I2/H2,"") | K2: =IF(J2="","",J2/Inputs!$B$1) | L2: Generic or other | M2: ALPHA PHARMA INDUSTRY | N2: Alpha Pharma Industry | O2: 1105269639
C3: LINAGLIPTIN | D3: OLPUNTRAMET | E3: 1000,25 | F3: mg | G3: Film-coated tablet | H3: 60 | I3: 130.9 | J3: =IF(H3>0,I3/H3,"") | K3: =IF(J3="","",J3/Inputs!$B$1) | L3: Generic or other | M3: ALPHA PHARMA INDUSTRY | N3: Alpha Pharma Industry | O3: 1105269640
A4: A01BX | C4: CANAGLIFLOZIN | D4: INVOKANA 100 mg film-coated tablet | E4: 100 | F4: mg | G4: Film-coated tablet | H4: 30 | I4: 159 | J4: =IF(H4>0,I4/H4,"") | K4: =IF(J4="","",J4/Inputs!$B$1) | L4: Originator | M4: JANSSEN PHARMACEUTICA N.V | N4: Farouk, Maamoun Tamer & CO | O4: 0703221821
A5: A01BX | C5: CANAGLIFLOZIN | D5: INVOKANA 300 mg film-coated tablet | E5: 300 | F5: mg | G5: Film-coated tablet | H5: 30 | I5: 159 | J5: =IF(H5>0,I5/H5,"") | K5: =IF(J5="","",J5/Inputs!$B$1) | L5: Originator | M5: JANSSEN PHARMACEUTICA N.V | N5: Farouk, Maamoun Tamer & CO | O5: 2106222241
A6: A02BC | C6: SITAGLIPTIN | D6: GLIPTEN 100MG F.C. TABLET | E6: 100 | F6: mg | G6: Gastro-resistant tablet | H6: 15 | I6: 98.2 | J6: =IF(H6>0,I6/H6,"") | K6: =IF(J6="","",J6/Inputs!$B$1) | L6: Generic or other | M6: ACINO PHARMA AG | N6: Cigalah GroupAcino Arabia for trading LLC | O6: 2801256767
A7: A04AA | C7: NETUPITANT | D7: AKYNZEO 300 mg/0.5 mg hard capsules | E7: 300,0.5 | F7: mg | G7: Capsule, hard | H7: 1 | I7: 306.7 | J7: =IF(H7>0,I7/H7,"") | K7: =IF(J7="","",J7/Inputs!$B$1) | L7: Originator | M7: Helsinn Birex Pharmaceuticals Ltd | N7: Cigalah Group | O7: 1303257068
A8: A04AD | B8: Other antiemetics | C8: APREPITANT | D8: ENEVOM 80 MG CAPSULE | E8: 80 | F8: mg | G8: Capsule, hard | H8: 1 | I8: 79.05 | J8: =IF(H8>0,I8/H8,"") | K8: =IF(J8="","",J8/Inputs!$B$1) | L8: Generic or other | M8: MS PHARMA for Pharmaceuticals | N8: Cigalah Group | O8: 3004257315
A9: A04AD | B9: Other antiemetics | C9: APREPITANT | D9: ENEVOM 125 MG CAPSULE | E9: 125 | F9: mg | G9: Capsule, hard | H9: 1 | I9: 79.05 | J9: =IF(H9>0,I9/H9,"") | K9: =IF(J9="","",J9/Inputs!$B$1) | L9: Generic or other | M9: MS PHARMA for Pharmaceuticals | N9: Cigalah Group | O9: 3004257316
A10: A04AD | B10: Other antiemetics | C10: APREPITANT | D10: Fosaprepitant SPC | E10: 150 | F10: mg | G10: powder for solution for injection | H10: 1 | I10: 200 | J10: =IF(H10>0,I10/H10,"") | K10: =IF(J10="","",J10/Inputs!$B$1) | L10: Generic or other | M10: SUDAIR PHARMA COMPANY | N10: SUDAIR PHARMA COMPANY | O10: 0902210504
A11: A07AA | B11: Intestinal anti-infectives | C11: FIDAXOMICIN | D11: DIFICLIR 200 mg Film Coated Tablet | E11: 200 | F11: mg | G11: Film-coated tablet | H11: 20 | I11: 5677.5 | J11: =IF(H11>0,I11/H11,"") | K11: =IF(J11="","",J11/Inputs!$B$1) | L11: Originator | M11: Tillotts Pharma GmbH | N11: ALHAYA MEDICAL CO | O11: 0305233586
A12: A07CA | C12: LINAGLIPTIN | D12: GLYXAMBI | E12: 10,5 | F12: g | G12: Powder for oral solution in sachet | H12: 10 | I12: 226.05 | J12: =IF(H12>0,I12/H12,"") | K12: =IF(J12="","",J12/Inputs!$B$1) | L12: Generic or other | M12: National Pharmaceutical Industries Co SAOC | N12: ZIMMO TRADING ESTABLISHMENTEBRAHIM M. ALMANA & BROS. CO. | O12: 2710246117
A13: A07CA | C13: VILDAGLIPTIN | D13: VILTIN 50 MG TABLET | E13: 50 | F13: g | G13: Powder for oral solution in sachet | H13: 50 | I13: 66.5 | J13: =IF(H13>0,I13/H13,"") | K13: =IF(J13="","",J13/Inputs!$B$1) | L13: Generic or other | M13: National Pharmaceutical Industries Co SAOC | N13: ZIMMO TRADING ESTABLISHMENTEBRAHIM M. ALMANA & BROS. CO. | O13: 0406269864
A14: A10BA | C14: SITAGLIPTIN | D14: Glycimille | E14: 850/50 | F14: mg | G14: Film-coated tablet | H14: 60 | I14: 90.6 | J14: =IF(H14>0,I14/H14,"") | K14: =IF(J14="","",J14/Inputs!$B$1) | L14: Generic or other | M14: Pharco International pharmaceutical company | N14: Pharco International pharmaceutical companyCigalah Group | O14: 1506257555
A15: A10BA | C15: SITAGLIPTIN | D15: Glycimille | E15: 1000,50 | F15: mg | G15: Film-coated tablet | H15: 60 | I15: 93.85 | J15: =IF(H15>0,I15/H15,"") | K15: =IF(J15="","",J15/Inputs!$B$1) | L15: Generic or other | M15: Pharco International pharmaceutical company | N15: Pharco International pharmaceutical companyCigalah Group | O15: 1202269140
A16: A10BA | C16: SITAGLIPTIN | D16: Xitamet | E16: 850,50 | F16: mg | G16: Film-coated tablet | H16: 56 | I16: 88 | J16: =IF(H16>0,I16/H16,"") | K16: =IF(J16="","",J16/Inputs!$B$1) | L16: Generic or other | M16: AJA PHARMACEUTICAL INDUSTRIES | N16: AJA PHARMACEUTICAL INDUSTRIES | O16: 0306257537
A17: A10BA | C17: SITAGLIPTIN | D17: Sitagliptin/Metformin Cooper | E17: 850,50 | F17: mg | G17: Film-coated tablet | H17: 60 | I17: 94.3 | J17: =IF(H17>0,I17/H17,"") | K17: =IF(J17="","",J17/Inputs!$B$1) | L17: Generic or other | M17: Cooper Pharma Arabia | N17: ARAC HEALTHCARE | O17: 2811258675
A18: A10BA | C18: SITAGLIPTIN | D18: SITagliptin - MetFORMIN Cooper | E18: 1000,50 | F18: mg | G18: Film-coated tablet | H18: 60 | I18: 97.7 | J18: =IF(H18>0,I18/H18,"") | K18: =IF(J18="","",J18/Inputs!$B$1) | L18: Generic or other | M18: Cooper Pharma Arabia | N18: ARAC HEALTHCARE | O18: 1002269116
A19: A10BA | C19: SITAGLIPTIN | D19: Xitamet | E19: 1000,50 | F19: mg | G19: Film-coated tablet | H19: 56 | I19: 91.2 | J19: =IF(H19>0,I19/H19,"") | K19: =IF(J19="","",J19/Inputs!$B$1) | L19: Generic or other | M19: AJA PHARMACEUTICAL INDUSTRIES | N19: AJA PHARMACEUTICAL INDUSTRIES | O19: 0306257538
A20: A10BA | C20: SITAGLIPTIN | D20: Sitavic XR | E20: 1000,100 | F20: mg | G20: Modified-release film-coated tablet | H20: 30 | I20: 126.5 | J20: =IF(H20>0,I20/H20,"") | K20: =IF(J20="","",J20/Inputs!$B$1) | L20: Generic or other | M20: Jamjoom Pharmaceuticals Factory Company | N20: JAMJOOM PHARMACEUTICALS CO. LTD. | O20: 1904269457
A21: A10BD | B21: Diabetes combinations | C21: ALOGLIPTIN | D21: VIPDOMET 12.5 mg/500 mg TABLETS | E21: 500,12.5 | F21: mg | G21: Film-coated tablet | H21: 56 | I21: 109.9 | J21: =IF(H21>0,I21/H21,"") | K21: =IF(J21="","",J21/Inputs!$B$1) | L21: Originator | M21: Jazeera Pharmaceutical Industries (JPI) | N21: Abdulrehman Algosaibi G.T.C. | O21: 2201233131
A22: A10BD | B22: Diabetes combinations | C22: ALOGLIPTIN | D22: VIPDOMET 12.5 mg/1000 mg TABLETS | E22: 1000,12.5 | F22: mg | G22: Film-coated tablet | H22: 56 | I22: 117.45 | J22: =IF(H22>0,I22/H22,"") | K22: =IF(J22="","",J22/Inputs!$B$1) | L22: Originator | M22: Jazeera Pharmaceutical Industries (JPI) | N22: Abdulrehman Algosaibi G.T.C. | O22: 2201233133
A23: A10BD | B23: Diabetes combinations | C23: ALOGLIPTIN | D23: INCRESYNC 25/15 mg Tablet | E23: 25,15 | F23: mg | G23: Tablet | H23: 28 | I23: 137.6 | J23: =IF(H23>0,I23/H23,"") | K23: =IF(J23="","",J23/Inputs!$B$1) | L23: Generic or other | M23: Jazeera Pharmaceutical Industries (JPI) | N23: Abdulrehman Algosaibi G.T.C. | O23: 0603245026
A24: A10BD | B24: Diabetes combinations | C24: ALOGLIPTIN | D24: CYERO 25/15 mg Tablet | E24: 25,15 | F24: mg | G24: Film-coated tablet | H24: 28 | I24: 137.6 | J24: =IF(H24>0,I24/H24,"") | K24: =IF(J24="","",J24/Inputs!$B$1) | L24: Generic or other | M24: BATTERJEE PHARMACETICAL FACTORY | N24: BATTERJEE PHARMACEUTICAL FACTORY | O24: 2705257465
A25: A10BD | B25: Diabetes combinations | C25: ALOGLIPTIN | D25: INCRESYNC 25/30 mg Tablet | E25: 25,30 | F25: mg | G25: Tablet | H25: 28 | I25: 159.75 | J25: =IF(H25>0,I25/H25,"") | K25: =IF(J25="","",J25/Inputs!$B$1) | L25: Generic or other | M25: Jazeera Pharmaceutical Industries (JPI) | N25: Abdulrehman Algosaibi G.T.C. | O25: 0603245025
A26: A10BD | B26: Diabetes combinations | C26: ALOGLIPTIN | D26: CYERO 25/30 mg Tablet | E26: 25,30 | F26: mg | G26: Film-coated tablet | H26: 28 | I26: 159.75 | J26: =IF(H26>0,I26/H26,"") | K26: =IF(J26="","",J26/Inputs!$B$1) | L26: Generic or other | M26: BATTERJEE PHARMACETICAL FACTORY | N26: BATTERJEE PHARMACEUTICAL FACTORY | O26: 2705257466
A27: A10BD | B27: Diabetes combinations | C27: DAPAGLIFLOZIN | D27: Depaxamet | E27: 5,1000 | F27: mg | G27: Film-coated tablet | H27: 30 | I27: 54.85 | J27: =IF(H27>0,I27/H27,"") | K27: =IF(J27="","",J27/Inputs!$B$1) | L27: Generic or other | M27: Pharco International pharmaceutical company | N27: Pharco International pharmaceutical companyCigalah Group | O27: 2704269537
A28: A10BD | B28: Diabetes combinations | C28: DAPAGLIFLOZIN | D28: Depaxamet | E28: 5,500 | F28: mg | G28: Film-coated tablet | H28: 30 | I28: 54.85 | J28: =IF(H28>0,I28/H28,"") | K28: =IF(J28="","",J28/Inputs!$B$1) | L28: Generic or other | M28: Pharco International pharmaceutical company | N28: Pharco International pharmaceutical companyCigalah Group | O28: 2704269535
A29: A10BD | B29: Diabetes combinations | C29: DAPAGLIFLOZIN | D29: Dapazin Met XR | E29: 5,1000 | F29: mg | G29: Modified-release film-coated tablet | H29: 28 | I29: 51.2 | J29: =IF(H29>0,I29/H29,"") | K29: =IF(J29="","",J29/Inputs!$B$1) | L29: Generic or other | M29: Jamjoom Pharmaceuticals Factory Company | N29: JAMJOOM PHARMACEUTICALS CO. LTD. | O29: 0110260613
A30: A10BD | B30: Diabetes combinations | C30: DAPAGLIFLOZIN | D30: Divinusmet | E30: 1000,5 | F30: mg | G30: Film-coated tablet | H30: 60 | I30: 119.4 | J30: =IF(H30>0,I30/H30,"") | K30: =IF(J30="","",J30/Inputs!$B$1) | L30: Generic or other | M30: Jazeera Pharmaceutical Industries (JPI) | N30: Jazeera Pharmaceutical Industries (JPI) | O30: 0206210763
A31: A10BD | B31: Diabetes combinations | C31: DAPAGLIFLOZIN | D31: XIGDUO XR 5 mg/1000 mg Film Coted Tablet | E31: 1000,5 | F31: mg | G31: Film-coated tablet | H31: 56 | I31: 128 | J31: =IF(H31>0,I31/H31,"") | K31: =IF(J31="","",J31/Inputs!$B$1) | L31: Originator | M31: AstraZeneca AB | N31: Saudi International Trading Company LTD | O31: 1309234197
A32: A10BD | B32: Diabetes combinations | C32: DAPAGLIFLOZIN | D32: Depaxamet | E32: 10,500 | F32: mg | G32: Film-coated tablet | H32: 30 | I32: 104.95 | J32: =IF(H32>0,I32/H32,"") | K32: =IF(J32="","",J32/Inputs!$B$1) | L32: Generic or other | M32: Pharco International pharmaceutical company | N32: Pharco International pharmaceutical companyCigalah Group | O32: 2704269534
... A226: A10BK | B226: SGLT2 inhibitors | C226: EMPAGLIFLOZIN | D226: Monzeva | E226: 10 | F226: mg | G226: Film-coated tablet | H226: 30 | I226: 135.15 | J226: =IF(H226>0,I226/H226,"") | K226: =IF(J226="","",J226/Inputs!$B$1) | L226: Generic or other | M226: SUDAIR PHARMA COMPANY | N226: SUDAIR PHARMA COMPANY | O226: 1308245764
A227: A10BX | C227: DAPAGLIFLOZIN | D227: DIVINUS 5 mg film-coated tablet | E227: 5 | F227: mg | G227: Film-coated tablet | H227: 30 | I227: 151 | J227: =IF(H227>0,I227/H227,"") | K227: =IF(J227="","",J227/Inputs!$B$1) | L227: Generic or other | M227: Jazeera Pharmaceutical Industries (JPI) | N227: Jazeera Pharmaceutical Industries (JPI) | O227: 2511246336
A228: A10BX | C228: DAPAGLIFLOZIN | D228: DIVINUS 10 mg film-coated tablet | E228: 10 | F228: mg | G228: Film-coated tablet | H228: 30 | I228: 151 | J228: =IF(H228>0,I228/H228,"") | K228: =IF(J228="","",J228/Inputs!$B$1) | L228: Generic or other | M228: Jazeera Pharmaceutical Industries (JPI) | N228: Jazeera Pharmaceutical Industries (JPI) | O228: 1911246258
A229: A10BX | C229: EMPAGLIFLOZIN | D229: JARDIANCE 10 mg film-coated tablet | E229: 10 | F229: mg | G229: Film-coated tablet | H229: 30 | I229: 159 | J229: =IF(H229>0,I229/H229,"") | K229: =IF(J229="","",J229/Inputs!$B$1) | L229: Originator | M229: BOEHRINGER INGELHEIM | N229: Cigalah Group | O229: 2810211247
A230: A10BX | C230: EMPAGLIFLOZIN | D230: JARDIANCE 25 mg film-coated tablet | E230: 25 | F230: mg | G230: Film-coated tablet | H230: 30 | I230: 159 | J230: =IF(H230>0,I230/H230,"") | K230: =IF(J230="","",J230/Inputs!$B$1) | L230: Originator | M230: BOEHRINGER INGELHEIM | N230: Cigalah Group | O230: 2810211246
A231: B05CB | C231: DAPAGLIFLOZIN | D231: FORXIGA 10 mg film-coated tablet | E231: 10 | F231: % | G231: Solution for injection | H231: 1 | I231: 159 | J231: =IF(H231>0,I231/H231,"") | K231: =IF(J231="","",J231/Inputs!$B$1) | L231: Originator | M231: Pharmaceutical Solution Industries (PSI) | N231: Pharmaceutical Solution Industries (PSI) | O231: 1807245616
A232: B05CB | C232: DAPAGLIFLOZIN | D232: FORXIGA 5 mg film-coated tablet | E232: 5 | F232: % | G232: Solution for injection | H232: 1 | I232: 159 | J232: =IF(H232>0,I232/H232,"") | K232: =IF(J232="","",J232/Inputs!$B$1) | L232: Originator | M232: Pharmaceutical Solution Industries (PSI) | N232: Pharmaceutical Solution Industries (PSI) | O232: 1807245616
A233: B05CB | C233: NIVOLUMAB | D233: OPDIVO 10 mg/ml solution for injection | E233: 10 | F233: % | G233: Solution for injection | H233: 1 | I233: 3385.15 | J233: =IF(H233>0,I233/H233,"") | K233: =IF(J233="","",J233/Inputs!$B$1) | L233: Originator | M233: Pharmaceutical Solution Industries (PSI) | N233: Pharmaceutical Solution Industries (PSI) | O233: 1807245616
...

Sheet Generic pressure
A1: Ingredient | B1: MSD products | C1: MSD lowest per unit SAR | D1: Other versions | E1: Generic or other | F1: Cheapest generic per unit SAR | G1: Cheapest vs MSD
A2: SITAGLIPTIN | B2: JANUMET; JANUMET XR; JANUVIA 100MG F.C. TABLETS; JANUVIA 25 mg; JANUVIA 50 mg | C2: =_xlfn.MINIFS(Products!$J$2:$J$339,Products!$C$2:$C$339,A2,Products!$L$2:$L$339,"MSD") | D2: =COUNTIFS(Products!$C$2:$C$339,A2,Products!$L$2:$L$339,"<>MSD") | E2: =COUNTIFS(Products!$C$2:$C$339,A2,Products!$L$2:$L$339,"Generic or other") | F2: =IF(E2=0,"",_xlfn.MINIFS(Products!$J$2:$J$339,Products!$C$2:$C$339,A2,Products!$L$2:$L$339,"Generic or other")) | G2: =IF(F2="","",F2/C2-1)
A3: SUGAMMADEX | B3: BRIDION 100 MG/ML SOLUTION FOR INJECTION; BRIDION 100 mg/ml Solution for Injection | C3: =_xlfn.MINIFS(Products!$J$2:$J$339,Products!$C$2:$C$339,A3,Products!$L$2:$L$339,"MSD") | D3: =COUNTIFS(Products!$C$2:$C$339,A3,Products!$L$2:$L$339,"<>MSD") | E3: =COUNTIFS(Products!$C$2:$C$339,A3,Products!$L$2:$L$339,"Generic or other") | F3: =IF(E3=0,"",_xlfn.MINIFS(Products!$J$2:$J$339,Products!$C$2:$C$339,A3,Products!$L$2:$L$339,"Generic or other")) | G3: =IF(F3="","",F3/C3-1)
A4: RALTEGRAVIR | B4: ISENTRESS 600MG F.C.TABLET | C4: =_xlfn.MINIFS(Products!$J$2:$J$339,Products!$C$2:$C$339,A4,Products!$L$2:$L$339,"MSD") | D4: =COUNTIFS(Products!$C$2:$C$339,A4,Products!$L$2:$L$339,"<>MSD") | E4: =COUNTIFS(Products!$C$2:$C$339,A4,Products!$L$2:$L$339,"Generic or other") | F4: =IF(E4=0,"",_xlfn.MINIFS(Products!$J$2:$J$339,Products!$C$2:$C$339,A4,Products!$L$2:$L$339,"Generic or other")) | G4: =IF(F4="","",F4/C4-1)
A5: BELZUTIFAN | B5: Welireg | C5: =_xlfn.MINIFS(Products!$J$2:$J$339,Products!$C$2:$C$339,A5,Products!$L$2:$L$339,"MSD") | D5: =COUNTIFS(Products!$C$2:$C$339,A5,Products!$L$2:$L$339,"<>MSD") | E5: =COUNTIFS(Products!$C$2:$C$339,A5,Products!$L$2:$L$339,"Generic or other") | F5: =IF(E5=0,"",_xlfn.MINIFS(Products!$J$2:$J$339,Products!$C$2:$C$339,A5,Products!$L$2:$L$339,"Generic or other")) | G5: =IF(F5="","",F5/C5-1)
A6: Hepatitis B vaccines | B6: RECOMBIVAX HB | C6: =_xlfn.MINIFS(Products!$J$2:$J$339,Products!$C$2:$C$339,A6,Products!$L$2:$L$339,"MSD") | D6: =COUNTIFS(Products!$C$2:$C$339,A6,Products!$L$2:$L$339,"<>MSD") | E6: =COUNTIFS(Products!$C$2:$C$339,A6,Products!$L$2:$L$339,"Generic or other") | F6: =IF(E6=0,"",_xlfn.MINIFS(Products!$J$2:$J$339,Products!$C$2:$C$339,A6,Products!$L$2:$L$339,"Generic or other")) | G6: =IF(F6="","",F6/C6-1)
A7: CEFTOLOZANE | B7: ZERBAXA Powder For Injection Vial | C7: =_xlfn.MINIFS(Products!$J$2:$J$339,Products!$C$2:$C$339,A7,Products!$L$2:$L$339,"MSD") | D7: =COUNTIFS(Products!$C$2:$C$339,A7,Products!$L$2:$L$339,"<>MSD") | E7: =COUNTIFS(Products!$C$2:$C$339,A7,Products!$L$2:$L$339,"Generic or other") | F7: =IF(E7=0,"",_xlfn.MINIFS(Products!$J$2:$J$339,Products!$C$2:$C$339,A7,Products!$L$2:$L$339,"Generic or other")) | G7: =IF(F7="","",F7/C7-1)
A8: DORAVIRINE | B8: Delstrigo; Pifeltro | C8: =_xlfn.MINIFS(Products!$J$2:$J$339,Products!$C$2:$C$339,A8,Products!$L$2:$L$339,"MSD") | D8: =COUNTIFS(Products!$C$2:$C$339,A8,Products!$L$2:$L$339,"<>MSD") | E8: =COUNTIFS(Products!$C$2:$C$339,A8,Products!$L$2:$L$339,"Generic or other") | F8: =IF(E8=0,"",_xlfn.MINIFS(Products!$J$2:$J$339,Products!$C$2:$C$339,A8,Products!$L$2:$L$339,"Generic or other")) | G8: =IF(F8="","",F8/C8-1)
A9: HPV vaccines | B9: Gardasil 9 | C9: =_xlfn.MINIFS(Products!$J$2:$J$339,Products!$C$2:$C$339,A9,Products!$L$2:$L$339,"MSD") | D9: =COUNTIFS(Products!$C$2:$C$339,A9,Products!$L$2:$L$339,"<>MSD") | E9: =COUNTIFS(Products!$C$2:$C$339,A9,Products!$L$2:$L$339,"Generic or other") | F9: =IF(E9=0,"",_xlfn.MINIFS(Products!$J$2:$J$339,Products!$C$2:$C$339,A9,Products!$L$2:$L$339,"Generic or other")) | G9: =IF(F9="","",F9/C9-1)
A10: PEMBROLIZUMAB | B10: KEYTRUDA 25 mg/ml Concentrate For Solution For Infusion; Keytruda | C10: =_xlfn.MINIFS(Products!$J$2:$J$339,Products!$C$2:$C$339,A10,Products!$L$2:$L$339,"MSD") | D10: =COUNTIFS(Products!$C$2:$C$339,A10,Products!$L$2:$L$339,"<>MSD") | E10: =COUNTIFS(Products!$C$2:$C$339,A10,Products!$L$2:$L$339,"Generic or other") | F10: =IF(E10=0,"",_xlfn.MINIFS(Products!$J$2:$J$339,Products!$C$2:$C$339,A10,Products!$L$2:$L$339,"Generic or other")) | G10: =IF(F10="","",F10/C10-1)
A11: Measles, mumps and rubella vaccines | B11: M.M.R II 0.5ML VACCINE+ 0.7ML DILUENT | C11: =_xlfn.MINIFS(Products!$J$2:$J$339,Products!$C$2:$C$339,A11,Products!$L$2:$L$339,"MSD") | D11: =COUNTIFS(Products!$C$2:$C$339,A11,Products!$L$2:$L$339,"<>MSD") | E11: =COUNTIFS(Products!$C$2:$C$339,A11,Products!$L$2:$L$339,"Generic or other") | F11: =IF(E11=0,"",_xlfn.MINIFS(Products!$J$2:$J$339,Products!$C$2:$C$339,A11,Products!$L$2:$L$339,"Generic or other")) | G11: =IF(F11="","",F11/C11-1)
A12: LETERMOVIR | B12: PREVYMIS | C12: =_xlfn.MINIFS(Products!$J$2:$J$339,Products!$C$2:$C$339,A12,Products!$L$2:$L$339,"MSD") | D12: =COUNTIFS(Products!$C$2:$C$339,A12,Products!$L$2:$L$339,"<>MSD") | E12: =COUNTIFS(Products!$C$2:$C$339,A12,Products!$L$2:$L$339,"Generic or other") | F12: =IF(E12=0,"",_xlfn.MINIFS(Products!$J$2:$J$339,Products!$C$2:$C$339,A12,Products!$L$2:$L$339,"Generic or other")) | G12: =IF(F12="","",F12/C12-1)
A13: Pneumococcal vaccines | B13: Capvaxive; Pneumovax 23 Pneumococcal Vaccine Polyvalent; Vaxneuvance | C13: =_xlfn.MINIFS(Products!$J$2:$J$339,Products!$C$2:$C$339,A13,Products!$L$2:$L$339,"MSD") | D13: =COUNTIFS(Products!$C$2:$C$339,A13,Products!$L$2:$L$339,"<>MSD") | E13: =COUNTIFS(Products!$C$2:$C$339,A13,Products!$L$2:$L$339,"Generic or other") | F13: =IF(E13=0,"",_xlfn.MINIFS(Products!$J$2:$J$339,Products!$C$2:$C$339,A13,Products!$L$2:$L$339,"Generic or other")) | G13: =IF(F13="","",F13/C13-1)
... A17: Varicella and zoster vaccines | B17: VARIVAX 1350 PFU VIAL | C17: =_xlfn.MINIFS(Products!$J$2:$J$339,Products!$C$2:$C$339,A17,Products!$L$2:$L$339,"MSD") | D17: =COUNTIFS(Products!$C$2:$C$339,A17,Products!$L$2:$L$339,"<>MSD") | E17: =COUNTIFS(Products!$C$2:$C$339,A17,Products!$L$2:$L$339,"Generic or other") | F17: =IF(E17=0,"",_xlfn.MINIFS(Products!$J$2:$J$339,Products!$C$2:$C$339,A17,Products!$L$2:$L$339,"Generic or other")) | G17: =IF(F17="","",F17/C17-1)

Sheet Reference pricing
A1: Brand | B1: US pack | C1: US NADAC per tablet USD | D1: Saudi product | E1: Saudi per tablet USD | F1: US / Saudi
A2: JANUVIA | B2: JANUVIA 100 MG TABLET | C2: 10.55179 | D2: JANUVIA 100MG F.C. TABLETS (100mg, pack of 28) | E2: =_xlfn.MINIFS(Products!$K$2:$K$339,Products!$D$2:$D$339,"JANUVIA 100MG F.C. TABLETS",Products!$H$2:$H$339,28,Products!$L$2:$L$339,"MSD") | F2: =C2/E2
A3: JANUMET | B3: JANUMET 50-1,000 MG TABLET | C3: 5.27929 | D3: JANUMET (1000,50mg, pack of 56) | E3: =_xlfn.MINIFS(Products!$K$2:$K$339,Products!$D$2:$D$339,"JANUMET",Products!$H$2:$H$339,56,Products!$L$2:$L$339,"MSD") | F3: =C3/E3
A4: STEGLATRO | B4: STEGLATRO 15 MG TABLET | C4: 11.4425 | D4: no same-strength tablet in the SFDA list
A5: ISENTRESS | B5: ISENTRESS 400 MG TABLET | C5: 34.53888 | D5: no same-strength tablet in the SFDA list
A6: PIFELTRO | B6: PIFELTRO 100 MG TABLET | C6: 60.78687 | D6: Pifeltro (100mg, pack of 30) | E6: =_xlfn.MINIFS(Products!$K$2:$K$339,Products!$D$2:$D$339,"Pifeltro",Products!$H$2:$H$339,30,Products!$L$2:$L$339,"MSD") | F6: =C6/E6
A7: BELSOMRA | B7: BELSOMRA 20 MG TABLET | C7: 15.20528 | D7: no same-strength tablet in the SFDA list
A8: DELSTRIGO | B8: DELSTRIGO 100-300-300 MG TAB | C8: 93.06069 | D8: Delstrigo (100,300,245mg, pack of 30) | E8: =_xlfn.MINIFS(Products!$K$2:$K$339,Products!$D$2:$D$339,"Delstrigo",Products!$H$2:$H$339,30,Products!$L$2:$L$339,"MSD") | F8: =C8/E8
A9: DIFICID | B9: DIFICID 200 MG TABLET | C9: 248.37854 | D9: no same-strength tablet in the SFDA list

Sheet Validation
A1: Id | B1: Check | C1: Status | D1: Result | E1: Rule
A2: V01 | B2: List rows without an SFDA id are quarantined | C2: warn | D2: 1 quarantined (Torixia) | E2: a row without a details link cannot be traced; it is kept aside, not loaded
A3: V02 | B3: Ids are unique after de-duplication | C3: pass | D3: 8,207 rows, 8,207 ids | E3: one row per id
A4: V03 | B4: Share of the list's rows that are distinct products | C4: warn | D4: 8,208 distinct of 9,173 rows read (89.5%); 459 pages of up to 20 (9,180) | E4: the list's order shifts between pages, so a page read later can repeat products and skip others; class products are filled in by searching each ingredient (V08)
A5: V04 | B5: Every product has a positive public price | C5: warn | D5: 2 without | E5: price > 0 SAR
A6: V05 | B6: Trade name, scientific name and dosage form are filled | C6: warn | D6: 1 rows missing one | E6: 0
A7: V06 | B7: Detail pages read for every followed product | C7: pass | D7: 338 read, 0 failed | E7: 0 failures
A8: V07 | B8: Followed products carry an ATC code | C8: pass | D8: 2 without (OLPUNTRAMET, OLPUNTRAMET) | E8: at most 5% without
A9: V08 | B9: Products found only by the ingredient search, not in the list read | C9: info | D9: 5 | E9: the list read missed them (see V03)
A10: V09 | B10: Pack size known for followed products | C10: pass | D10: 338 of 338 | E10: at least 90%, needed for price per unit
A11: V10 | B11: List price equals the price read again with the details | C11: warn | D11: 5 differ | E11: 0 (the two reads were minutes apart)
A12: V11 | B12: Database holds every staged row | C12: pass | D12: list 8,207, details 338 | E12: rows in = rows loaded
